<mujoco model="banana">
  <compiler angle="radian" meshdir="../meshes/banana" texturedir="../textures"/>
    <default>
        <default class="ycb_col">
            <geom contype="1" conaffinity="1" group="3" rgba=".4 .5 .6 1"/>
        </default>
        <default class="ycb_viz">
            <geom contype="0" conaffinity="0" type="mesh" mass="0"/>
        </default>
    </default>
  <asset>
    <texture type="2d" name="banana_tex" file="banana.png"/>
    <material name="banana_mat" texture="banana_tex" specular="0.5" shininess="0.5"/>
    <mesh file="textured.obj" name="banana"/>
    <mesh file="textured_collision_0.obj" name="banana_collision_0"/>
    <mesh file="textured_collision_1.obj" name="banana_collision_1"/>
    <mesh file="textured_collision_2.obj" name="banana_collision_2"/>
    <mesh file="textured_collision_3.obj" name="banana_collision_3"/>
    <mesh file="textured_collision_4.obj" name="banana_collision_4"/>
    <mesh file="textured_collision_5.obj" name="banana_collision_5"/>
  </asset>
  <worldbody>
    <body name="object">
      <geom class="ycb_viz" material="banana_mat" mesh="banana"/>
      <geom class="ycb_col" mesh="banana_collision_0" conaffinity="1" condim="4" friction="0.1 0.1 0.1" mass="0.023053405681108384" rgba="1 1 1 1" solimp="0.99 0.99 0.01" solref=".001 0.1" type="mesh" />
      <geom class="ycb_col" mesh="banana_collision_1" conaffinity="1" condim="4" friction="0.1 0.1 0.1" mass="0.027556421693865407" rgba="1 1 1 1" solimp="0.99 0.99 0.01" solref=".001 0.1" type="mesh" />
      <geom class="ycb_col" mesh="banana_collision_2" conaffinity="1" condim="4" friction="0.1 0.1 0.1" mass="0.007996179926755482" rgba="1 1 1 1" solimp="0.99 0.99 0.01" solref=".001 0.1" type="mesh" />
      <geom class="ycb_col" mesh="banana_collision_3" conaffinity="1" condim="4" friction="0.1 0.1 0.1" mass="0.006349115545010323" rgba="1 1 1 1" solimp="0.99 0.99 0.01" solref=".001 0.1" type="mesh" />
      <geom class="ycb_col" mesh="banana_collision_4" conaffinity="1" condim="4" friction="0.1 0.1 0.1" mass="0.0003986589581986802" rgba="1 1 1 1" solimp="0.99 0.99 0.01" solref=".001 0.1" type="mesh" />
      <geom class="ycb_col" mesh="banana_collision_5" conaffinity="1" condim="4" friction="0.1 0.1 0.1" mass="0.0006462181950617304" rgba="1 1 1 1" solimp="0.99 0.99 0.01" solref=".001 0.1" type="mesh" />
      <joint armature="0" axis="1 0 0" damping="0" limited="true" name="jnt_x" pos="0 0 0" range="-5. 5." stiffness="0" type="slide"/>
      <joint armature="0" axis="0 1 0" damping="0" limited="true" name="jnt_y" pos="0 0 0" range="-5. 5." stiffness="0" type="slide"/>
      <joint armature="0" axis="0 0 1" damping="0" limited="true" name="jnt_z" pos="0 0 0" range="-2. 2." stiffness="0" type="slide"/>
      <joint armature="0" damping="0" name="jnt_rot" pos="0 0 0" stiffness="0" type="ball"/>
    </body>
  </worldbody>
</mujoco>