<mujoco model="peach">
  <compiler angle="radian" meshdir="../meshes/peach" texturedir="../textures"/>
    <default>
        <default class="ycb_col">
            <geom contype="1" conaffinity="1" group="3" rgba=".4 .5 .6 1"/>
        </default>
        <default class="ycb_viz">
            <geom contype="0" conaffinity="0" type="mesh" mass="0"/>
        </default>
    </default>
  <asset>
    <texture type="2d" name="peach_tex" file="peach.png"/>
    <material name="peach_mat" texture="peach_tex" specular="0.5" shininess="0.5"/>
    <mesh file="textured.obj" name="peach"/>
    <mesh file="textured_collision_0.obj" name="peach_collision_0"/>
  </asset>
  <worldbody>
    <body name="peach">
      <geom class="ycb_viz" material="peach_mat" mesh="peach"/>
      <geom class="ycb_col" mesh="peach_collision_0" conaffinity="1" condim="4" friction="0.1 0.1 0.1" mass="0.03300000000000001" rgba="1 1 1 1" solimp="0.99 0.99 0.01" solref=".001 0.1" type="mesh" group="3"/>
      <joint armature="0" axis="1 0 0" damping="0" limited="true" name="jnt_x" pos="0 0 0" range="-5. 5." stiffness="0" type="slide"/>
      <joint armature="0" axis="0 1 0" damping="0" limited="true" name="jnt_y" pos="0 0 0" range="-5. 5." stiffness="0" type="slide"/>
      <joint armature="0" axis="0 0 1" damping="0" limited="true" name="jnt_z" pos="0 0 0" range="-2. 2." stiffness="0" type="slide"/>
      <joint armature="0" damping="0" name="jnt_rot" pos="0 0 0" stiffness="0" type="ball"/>
    </body>  
  </worldbody>
</mujoco>